Workbook

Sheet Synthèse
A1: LIMA → RIO DE JANEIRO — 17 jours, 100 % en bus
A2: Pérou · Bolivie · Paraguay · Brésil — 5 200 km de route, 5 nuits en bus, 12 nuits en auberge
A3: Une feuille par jour (J01 à J17). Coûts en monnaie locale et en dollars US, moyen de paiement indiqué ligne par ligne.
A5: Jour | B5: Étape | C5: Programme | D5: Nuit | E5: Budget USD min | F5: Budget USD max
A6: J1 | B6: LIMA (Pérou) | C6: Lima — centre historique puis bus de nuit vers Puno | D6: Bus (Lima → Puno) | E6: ='J01 - Lima'!G18 | F6: ='J01 - Lima'!H18
A7: J2 | B7: PUNO (Pérou) | C7: Arrivée sur le lac Titicaca — acclimatation | D7: Hostal Puno | E7: ='J02 - Puno'!G19 | F7: ='J02 - Puno'!H19
A8: J3 | B8: PUNO → COPACABANA (Bolivie) | C8: Passage de frontière à Kasani — côté bolivien du Titicaca | D8: Hostal Copacabana | E8: ='J03 - Puno-Copacabana'!G23 | F8: ='J03 - Puno-Copacabana'!H23
A9: J4 | B9: ISLA DEL SOL (Bolivie) | C9: Journée complète sur l'île du Soleil — berceau inca | D9: Hostal Copacabana | E9: ='J04 - Isla del Sol'!G19 | F9: ='J04 - Isla del Sol'!H19
A10: J5 | B10: COPACABANA → LA PAZ | C10: Détroit de Tiquina et descente sur La Paz | D10: Hostel La Paz | E10: ='J05 - Copacabana-La Paz'!G18 | F10: ='J05 - Copacabana-La Paz'!H18
A11: J6 | B11: LA PAZ — jour 1 | C11: Téléphériques, El Alto, marchés et miradors | D11: Hostel La Paz | E11: ='J06 - La Paz 1'!G20 | F11: ='J06 - La Paz 1'!H20
A12: J7 | B12: LA PAZ — jour 2 | C12: Route de la Mort à VTT, puis bus de nuit vers Santa Cruz | D12: Bus (La Paz → Santa Cruz) | E12: ='J07 - La Paz 2'!G17 | F12: ='J07 - La Paz 2'!H17
A13: J8 | B13: SANTA CRUZ (transit) | C13: Escale de 6 h puis départ pour le Chaco | D13: Bus (Santa Cruz → Asunción) | E13: ='J08 - Santa Cruz'!G18 | F13: ='J08 - Santa Cruz'!H18
A14: J9 | B14: CHACO → ASUNCIÓN (Paraguay) | C14: Traversée du Chaco et double frontière | D14: Hostel Asunción | E14: ='J09 - Chaco-Asuncion'!G17 | F14: ='J09 - Chaco-Asuncion'!H17
A15: J10 | B15: ASUNCIÓN — jour 1 | C15: Centre historique, Mercado 4 et Costanera | D15: Hostel Asunción | E15: ='J10 - Asuncion 1'!G20 | F15: ='J10 - Asuncion 1'!H20
A16: J11 | B16: ASUNCIÓN — jour 2 | C16: Lac Ypacaraí (Areguá) et préparation du grand bus | D16: Hostel Asunción | E16: ='J11 - Asuncion 2'!G17 | F16: ='J11 - Asuncion 2'!H17
A17: J12 | B17: ASUNCIÓN → SÃO PAULO | C17: 21 h 30 de bus et passage au Brésil par le Pont de l'Amitié | D17: Bus (Asunción → São Paulo) | E17: ='J12 - Asuncion-Sao Paulo'!G16 | F17: ='J12 - Asuncion-Sao Paulo'!H16
A18: J13 | B18: SÃO PAULO — jour 1 | C18: Arrivée à l'aube, Avenida Paulista et centre | D18: Auberge São Paulo | E18: ='J13 - Sao Paulo 1'!G19 | F18: ='J13 - Sao Paulo 1'!H19
A19: J14 | B19: SÃO PAULO — jour 2 | C19: Luz, Mercadão, Ibirapuera, Liberdade — puis bus de nuit | D19: Bus (São Paulo → Rio) | E19: ='J14 - Sao Paulo 2'!G19 | F19: ='J14 - Sao Paulo 2'!H19
A20: J15 | B20: RIO DE JANEIRO — jour 1 | C20: CHRIST RÉDEMPTEUR, Santa Teresa et Lapa | D20: Auberge Rio | E20: ='J15 - Rio 1'!G18 | F20: ='J15 - Rio 1'!H18
A21: J16 | B21: RIO DE JANEIRO — jour 2 | C21: Pain de Sucre, Copacabana et Ipanema | D21: Auberge Rio | E21: ='J16 - Rio 2'!G17 | F21: ='J16 - Rio 2'!H17
A22: J17 | B22: RIO DE JANEIRO — jour 3 | C22: Jardin botanique, Parque Lage, Maracanã et Porto Maravilha | D22: Auberge Rio | E22: ='J17 - Rio 3'!G16 | F22: ='J17 - Rio 3'!H16
A24: TOTAL SUR PLACE (J1 → J17) | E24: =SUM(E6:E22) | F24: =SUM(F6:F22)
A26: Sous-totaux par pays (USD)
B27: Pérou | C27: J1 – J3 | E27: =SUMIF('J01 - Lima'!$D$6:$D$16,"PEN",'J01 - Lima'!G6:G16)+SUMIF('J02 - Puno'!$D$6:$D$17,"PEN",'J02 - Puno'!G6:G17)+SUMIF('J03 - Puno-Copacabana'!$D$6:$D$21,"PEN",'J03 - Puno-Copacabana'!G6:G21) | F27: =SUMIF('J01 - Lima'!$D$6:$D$16,"PEN",'J01 - Lima'!H6:H16)+SUMIF('J02 - Puno'!$D$6:$D$17,"PEN",'J02 - Puno'!H6:H17)+SUMIF('J03 - Puno-Copacabana'!$D$6:$D$21,"PEN",'J03 - Puno-Copacabana'!H6:H21)
B28: Bolivie | C28: J3 – J9 | E28: =SUMIF('J03 - Puno-Copacabana'!$D$6:$D$21,"BOB",'J03 - Puno-Copacabana'!G6:G21)+SUMIF('J04 - Isla del Sol'!$D$6:$D$17,"BOB",'J04 - Isla del Sol'!G6:G17)+SUMIF('J05 - Copacabana-La Paz'!$D$6:$D$16,"BOB",'J05 - Copacabana-La Paz'!G6:G16)+SUMIF('J06 - La Paz 1'!$D$6:$D$18,"BOB",'J06 - La Paz 1'!G6:G18)+SUMIF('J07 - La Paz 2'!$D$6:$D$15,"BOB",'J07 - La Paz 2'!G6:G15)+SUMIF('J08 - Santa Cruz'!$D$6:$D$16,"BOB",'J08 - Santa Cruz'!G6:G16)+SUMIF('J09 - Chaco-Asuncion'!$D$6:$D$15,"BOB",'J09 - Chaco-Asuncion'!G6:G15) | F28: =SUMIF('J03 - Puno-Copacabana'!$D$6:$D$21,"BOB",'J03 - Puno-Copacabana'!H6:H21)+SUMIF('J04 - Isla del Sol'!$D$6:$D$17,"BOB",'J04 - Isla del Sol'!H6:H17)+SUMIF('J05 - Copacabana-La Paz'!$D$6:$D$16,"BOB",'J05 - Copacabana-La Paz'!H6:H16)+SUMIF('J06 - La Paz 1'!$D$6:$D$18,"BOB",'J06 - La Paz 1'!H6:H18)+SUMIF('J07 - La Paz 2'!$D$6:$D$15,"BOB",'J07 - La Paz 2'!H6:H15)+SUMIF('J08 - Santa Cruz'!$D$6:$D$16,"BOB",'J08 - Santa Cruz'!H6:H16)+SUMIF('J09 - Chaco-Asuncion'!$D$6:$D$15,"BOB",'J09 - Chaco-Asuncion'!H6:H15)
B29: Paraguay | C29: J9 – J12 | E29: =SUMIF('J09 - Chaco-Asuncion'!$D$6:$D$15,"PYG",'J09 - Chaco-Asuncion'!G6:G15)+SUMIF('J10 - Asuncion 1'!$D$6:$D$18,"PYG",'J10 - Asuncion 1'!G6:G18)+SUMIF('J11 - Asuncion 2'!$D$6:$D$15,"PYG",'J11 - Asuncion 2'!G6:G15)+SUMIF('J12 - Asuncion-Sao Paulo'!$D$6:$D$14,"PYG",'J12 - Asuncion-Sao Paulo'!G6:G14) | F29: =SUMIF('J09 - Chaco-Asuncion'!$D$6:$D$15,"PYG",'J09 - Chaco-Asuncion'!H6:H15)+SUMIF('J10 - Asuncion 1'!$D$6:$D$18,"PYG",'J10 - Asuncion 1'!H6:H18)+SUMIF('J11 - Asuncion 2'!$D$6:$D$15,"PYG",'J11 - Asuncion 2'!H6:H15)+SUMIF('J12 - Asuncion-Sao Paulo'!$D$6:$D$14,"PYG",'J12 - Asuncion-Sao Paulo'!H6:H14)
B30: Brésil | C30: J12 – J17 | E30: =SUMIF('J12 - Asuncion-Sao Paulo'!$D$6:$D$14,"BRL",'J12 - Asuncion-Sao Paulo'!G6:G14)+SUMIF('J13 - Sao Paulo 1'!$D$6:$D$17,"BRL",'J13 - Sao Paulo 1'!G6:G17)+SUMIF('J14 - Sao Paulo 2'!$D$6:$D$17,"BRL",'J14 - Sao Paulo 2'!G6:G17)+SUMIF('J15 - Rio 1'!$D$6:$D$16,"BRL",'J15 - Rio 1'!G6:G16)+SUMIF('J16 - Rio 2'!$D$6:$D$15,"BRL",'J16 - Rio 2'!G6:G15)+SUMIF('J17 - Rio 3'!$D$6:$D$14,"BRL",'J17 - Rio 3'!G6:G14) | F30: =SUMIF('J12 - Asuncion-Sao Paulo'!$D$6:$D$14,"BRL",'J12 - Asuncion-Sao Paulo'!H6:H14)+SUMIF('J13 - Sao Paulo 1'!$D$6:$D$17,"BRL",'J13 - Sao Paulo 1'!H6:H17)+SUMIF('J14 - Sao Paulo 2'!$D$6:$D$17,"BRL",'J14 - Sao Paulo 2'!H6:H17)+SUMIF('J15 - Rio 1'!$D$6:$D$16,"BRL",'J15 - Rio 1'!H6:H16)+SUMIF('J16 - Rio 2'!$D$6:$D$15,"BRL",'J16 - Rio 2'!H6:H15)+SUMIF('J17 - Rio 3'!$D$6:$D$14,"BRL",'J17 - Rio 3'!H6:H14)
A32: Fourchette basse : dortoir, repas de marché, bus publics, alternative économique à la Route de la Mort. Fourchette haute : chambres privées, restaurants, bus touristiques, Route de la Mort en VTT. Hors planning (vaccin, assurance, frais bancaires, réserve) : voir la feuille « Hors planning ».

Sheet Taux de change
A1: Taux de change — cellules d'entrée
A2: Relevés le 11/09/2026. Modifiez la colonne B : tout le classeur se recalcule.
A4: Devise | B4: Unités pour 1 USD | C4: Pays | D4: Remarque
A5: PEN | B5: 3.363 | C5: Pérou (sol, S/) | D5: Taux de marché. Retrait au DAB : S/ 18–25 de frais locaux en plus.
A6: BOB | B6: 12.04 | C6: Bolivie (boliviano, Bs) | D6: Taux officiel BCB. Marché parallèle ≈ Bs 11,75 : l'écart s'est refermé depuis la dévaluation de décembre 2025.
A7: PYG | B7: 5921.57 | C7: Paraguay (guaraní, Gs) | D7: Monnaie inéchangeable hors du Paraguay : ne gardez rien en sortant.
A8: BRL | B8: 5.115 | C8: Brésil (real, R$) | D8: Une carte type Revolut/Wise donne un meilleur taux que toutes les casas de câmbio.
A11: Légende : le bleu signale une valeur saisie à la main (donc modifiable). Tout le reste du classeur est calculé par formule.

Sheet Bus longue distance
A1: Les 7 trajets en bus
A2: Colonne vertébrale du voyage : 5 200 km, dont 5 nuits passées à bord.
A5: Jour | B5: Trajet | C5: Compagnies | D5: Distance | E5: Durée | F5: Devise | G5: Prix local min | H5: Prix local max | I5: Prix USD min | J5: Prix USD max
A6: J1 | B6: Lima → Puno | C6: Civa Excluciva, Cruz del Sur Suite | D6: 1 300 km | E6: 21 h – 22 h | F6: PEN | G6: 150 | H6: 230 | I6: =G6/INDEX('Taux de change'!$B$5:$B$8,MATCH($F6,'Taux de change'!$A$5:$A$8,0)) | J6: =H6/INDEX('Taux de change'!$B$5:$B$8,MATCH($F6,'Taux de change'!$A$5:$A$8,0))
A7: J3 | B7: Puno → Copacabana | C7: Trans Titicaca, Tour Perú, Trans Zela | D7: 150 km | E7: 3 h 30 – 4 h (frontière incluse) | F7: PEN | G7: 30 | H7: 45 | I7: =G7/INDEX('Taux de change'!$B$5:$B$8,MATCH($F7,'Taux de change'!$A$5:$A$8,0)) | J7: =H7/INDEX('Taux de change'!$B$5:$B$8,MATCH($F7,'Taux de change'!$A$5:$A$8,0))
A8: J5 | B8: Copacabana → La Paz | C8: Manco Kapac (public) / Bolivia Hop (touristique) | D8: 155 km | E8: 3 h 30 – 4 h + barge de Tiquina | F8: BOB | G8: 30 | H8: 100 | I8: =G8/INDEX('Taux de change'!$B$5:$B$8,MATCH($F8,'Taux de change'!$A$5:$A$8,0)) | J8: =H8/INDEX('Taux de change'!$B$5:$B$8,MATCH($F8,'Taux de change'!$A$5:$A$8,0))
A9: J7 | B9: La Paz → Santa Cruz | C9: Trans Copacabana, El Dorado (bus cama) | D9: 851 km | E9: 18 h | F9: BOB | G9: 232 | H9: 319 | I9: =G9/INDEX('Taux de change'!$B$5:$B$8,MATCH($F9,'Taux de change'!$A$5:$A$8,0)) | J9: =H9/INDEX('Taux de change'!$B$5:$B$8,MATCH($F9,'Taux de change'!$A$5:$A$8,0))
A10: J8 | B10: Santa Cruz → Asunción | C10: Stel Turismo, Río Paraguay | D10: 1 324 km | E10: 24 h (Ruta Transchaco) | F10: BOB | G10: 400 | H10: 520 | I10: =G10/INDEX('Taux de change'!$B$5:$B$8,MATCH($F10,'Taux de change'!$A$5:$A$8,0)) | J10: =H10/INDEX('Taux de change'!$B$5:$B$8,MATCH($F10,'Taux de change'!$A$5:$A$8,0))
A11: J12 | B11: Asunción → São Paulo | C11: Expreso Paraguay, NSA, Pluma | D11: 1 130 km | E11: 21 h 26 | F11: PYG | G11: 450000 | H11: 620000 | I11: =G11/INDEX('Taux de change'!$B$5:$B$8,MATCH($F11,'Taux de change'!$A$5:$A$8,0)) | J11: =H11/INDEX('Taux de change'!$B$5:$B$8,MATCH($F11,'Taux de change'!$A$5:$A$8,0))
A12: J14 | B12: São Paulo → Rio | C12: Viação 1001, Cometa, Águia Branca | D12: 429 km | E12: 6 h – 6 h 45 | F12: BRL | G12: 100 | H12: 200 | I12: =G12/INDEX('Taux de change'!$B$5:$B$8,MATCH($F12,'Taux de change'!$A$5:$A$8,0)) | J12: =H12/INDEX('Taux de change'!$B$5:$B$8,MATCH($F12,'Taux de change'!$A$5:$A$8,0))
A14: TOTAL TRANSPORT LONGUE DISTANCE | I14: =SUM(I6:I12) | J14: =SUM(J6:J12)
A16: Le bus Santa Cruz → Asunción ne part que les lundi, mardi, mercredi, vendredi et samedi à 19h00 : calez votre date de départ de Lima pour que le J8 tombe un de ces jours. Achetez-le au guichet du Terminal Bimodal : les agences en ligne facturent le double.

Sheet J01 - Lima
A1: JOUR 1 — LIMA (Pérou)
A2: Lima — centre historique puis bus de nuit vers Puno
A3: Altitude : 154 m
A5: Horaires | B5: Activité / prestation | C5: Détail, vigilance, alternative | D5: Devise | E5: Coût local min | F5: Coût local max | G5: Coût USD min | H5: Coût USD max | I5: Paiement
A6: 07h30–08h15 | B6: Petit-déjeuner : café + pan con chicharrón / jugo surtido (Miraflores) | D6: PEN | E6: 8 | F6: 15 | G6: =IF($D6="","",E6/INDEX('Taux de change'!$B$5:$B$8,MATCH($D6,'Taux de change'!$A$5:$A$8,0))) | H6: =IF($D6="","",F6/INDEX('Taux de change'!$B$5:$B$8,MATCH($D6,'Taux de change'!$A$5:$A$8,0))) | I6: Espèces
A7: 08h30–09h00 | B7: Metropolitano Miraflores → Centre (station Jr. de la Unión) + achat de la carte rechargeable | C7: Carte S/ 5,40 à l'achat + S/ 3,80 le trajet. Pas de CB aux guichets. | D7: PEN | E7: 6 | F7: 10 | G7: =IF($D7="","",E7/INDEX('Taux de change'!$B$5:$B$8,MATCH($D7,'Taux de change'!$A$5:$A$8,0))) | H7: =IF($D7="","",F7/INDEX('Taux de change'!$B$5:$B$8,MATCH($D7,'Taux de change'!$A$5:$A$8,0))) | I7: Espèces
A8: 09h00–10h00 | B8: Plaza Mayor + Cathédrale de Lima (nef, crypte, musée d'art religieux) | D8: PEN | E8: 30 | F8: 30 | G8: =IF($D8="","",E8/INDEX('Taux de change'!$B$5:$B$8,MATCH($D8,'Taux de change'!$A$5:$A$8,0))) | H8: =IF($D8="","",F8/INDEX('Taux de change'!$B$5:$B$8,MATCH($D8,'Taux de change'!$A$5:$A$8,0))) | I8: CB / esp.
A9: 10h00–11h30 | B9: Couvent San Francisco + catacombes (visite guidée obligatoire, 45 min) | D9: PEN | E9: 20 | F9: 25 | G9: =IF($D9="","",E9/INDEX('Taux de change'!$B$5:$B$8,MATCH($D9,'Taux de change'!$A$5:$A$8,0))) | H9: =IF($D9="","",F9/INDEX('Taux de change'!$B$5:$B$8,MATCH($D9,'Taux de change'!$A$5:$A$8,0))) | I9: CB / esp.
A10: 11h30–12h30 | B10: Jr. de la Unión, Plaza San Martín, Casa de Aliaga (extérieur), Mercado Central | I10: —
A11: 12h30–13h30 | B11: Almuerzo « menú del día » : entrée + plat + boisson (hors zone touristique) | D11: PEN | E11: 15 | F11: 25 | G11: =IF($D11="","",E11/INDEX('Taux de change'!$B$5:$B$8,MATCH($D11,'Taux de change'!$A$5:$A$8,0))) | H11: =IF($D11="","",F11/INDEX('Taux de change'!$B$5:$B$8,MATCH($D11,'Taux de change'!$A$5:$A$8,0))) | I11: Espèces
A12: 13h30–14h30 | B12: Uber / Cabify Centre → Terrapuerto Excluciva, Av. Javier Prado Este 1155 (La Victoria) | C12: Ne pas héler un taxi dans la rue à Lima. Uber, Cabify ou InDriver uniquement. | D12: PEN | E12: 25 | F12: 40 | G12: =IF($D12="","",E12/INDEX('Taux de change'!$B$5:$B$8,MATCH($D12,'Taux de change'!$A$5:$A$8,0))) | H12: =IF($D12="","",F12/INDEX('Taux de change'!$B$5:$B$8,MATCH($D12,'Taux de change'!$A$5:$A$8,0))) | I12: CB (in-app)
A13: 14h30–15h20 | B13: Enregistrement du sac en soute + tasa de embarque | D13: PEN | E13: 2 | F13: 2 | G13: =IF($D13="","",E13/INDEX('Taux de change'!$B$5:$B$8,MATCH($D13,'Taux de change'!$A$5:$A$8,0))) | H13: =IF($D13="","",F13/INDEX('Taux de change'!$B$5:$B$8,MATCH($D13,'Taux de change'!$A$5:$A$8,0))) | I13: Espèces
A14: 15h20–15h30 | B14: Eau 2 L + snacks pour 21 h de route | D14: PEN | E14: 12 | F14: 18 | G14: =IF($D14="","",E14/INDEX('Taux de change'!$B$5:$B$8,MATCH($D14,'Taux de change'!$A$5:$A$8,0))) | H14: =IF($D14="","",F14/INDEX('Taux de change'!$B$5:$B$8,MATCH($D14,'Taux de change'!$A$5:$A$8,0))) | I14: Espèces
A15: 15h30 | B15: BUS LIMA → PUNO — Civa « Excluciva » ou Cruz del Sur « Suite » · 1 300 km · 21 h–22 h · siège 180° · 2 repas + WC + wifi aléatoire | C15: Réserver 3–7 jours à l'avance sur civa.com.pe ou cruzdelsur.com.pe. Le bus grimpe de 0 à 4 500 m dans la nuit : soroche possible au réveil. | D15: PEN | E15: 150 | F15: 230 | G15: =IF($D15="","",E15/INDEX('Taux de change'!$B$5:$B$8,MATCH($D15,'Taux de change'!$A$5:$A$8,0))) | H15: =IF($D15="","",F15/INDEX('Taux de change'!$B$5:$B$8,MATCH($D15,'Taux de change'!$A$5:$A$8,0))) | I15: CB en ligne
A16: Nuit | B16: Nuit à bord — aucune nuit d'hébergement à payer | I16: —
A18: TOTAL JOUR 1 | G18: =SUM(G6:G16) | H18: =SUM(H6:H16)
A20: Détail par devise
A21: Total S/ (PEN) | E21: =SUMIF($D$6:$D$16,"PEN",E6:E16) | F21: =SUMIF($D$6:$D$16,"PEN",F6:F16)
A23: Colonnes E et F = fourchette basse / haute en monnaie locale. Colonnes G et H = conversion automatique via la feuille « Taux de change ».

Sheet J02 - Puno
A1: JOUR 2 — PUNO (Pérou)
A2: Arrivée sur le lac Titicaca — acclimatation
A3: Altitude : 3 827 m
A5: Horaires | B5: Activité / prestation | C5: Détail, vigilance, alternative | D5: Devise | E5: Coût local min | F5: Coût local max | G5: Coût USD min | H5: Coût USD max | I5: Paiement
A6: 06h00–07h00 | B6: Petit-déjeuner servi à bord (inclus en Excluciva / Suite) — sinon arrêt Arequipa ou Juliaca | D6: PEN | E6: 0 | F6: 12 | G6: =IF($D6="","",E6/INDEX('Taux de change'!$B$5:$B$8,MATCH($D6,'Taux de change'!$A$5:$A$8,0))) | H6: =IF($D6="","",F6/INDEX('Taux de change'!$B$5:$B$8,MATCH($D6,'Taux de change'!$A$5:$A$8,0))) | I6: Espèces
A7: 12h30–13h00 | B7: Arrivée Terminal Terrestre de Puno (Jr. Primero de Mayo) | I7: —
A8: 13h00–13h20 | B8: Mototaxi terminal → centre (1,5 km) | C8: Négocier avant de monter. Course standard S/ 5. | D8: PEN | E8: 5 | F8: 8 | G8: =IF($D8="","",E8/INDEX('Taux de change'!$B$5:$B$8,MATCH($D8,'Taux de change'!$A$5:$A$8,0))) | H8: =IF($D8="","",F8/INDEX('Taux de change'!$B$5:$B$8,MATCH($D8,'Taux de change'!$A$5:$A$8,0))) | I8: Espèces
A9: 13h20–14h00 | B9: Check-in hostal, quartier Jr. Lima / Plaza de Armas — lit en dortoir (chambre privée : S/ 70–110) | D9: PEN | E9: 35 | F9: 55 | G9: =IF($D9="","",E9/INDEX('Taux de change'!$B$5:$B$8,MATCH($D9,'Taux de change'!$A$5:$A$8,0))) | H9: =IF($D9="","",F9/INDEX('Taux de change'!$B$5:$B$8,MATCH($D9,'Taux de change'!$A$5:$A$8,0))) | I9: CB / esp.
A10: 14h00–15h00 | B10: Almuerzo : trucha frita du lac + mate de coca | D10: PEN | E10: 20 | F10: 30 | G10: =IF($D10="","",E10/INDEX('Taux de change'!$B$5:$B$8,MATCH($D10,'Taux de change'!$A$5:$A$8,0))) | H10: =IF($D10="","",F10/INDEX('Taux de change'!$B$5:$B$8,MATCH($D10,'Taux de change'!$A$5:$A$8,0))) | I10: Espèces
A11: 15h00–16h00 | B11: Repos obligatoire — acclimatation. Sorojchi Pills en pharmacie (Inkafarma) | C11: Monter de 154 m à 3 827 m en une nuit : ne rien forcer le premier après-midi, boire 3 L d'eau, éviter l'alcool. | D11: PEN | E11: 12 | F11: 18 | G11: =IF($D11="","",E11/INDEX('Taux de change'!$B$5:$B$8,MATCH($D11,'Taux de change'!$A$5:$A$8,0))) | H11: =IF($D11="","",F11/INDEX('Taux de change'!$B$5:$B$8,MATCH($D11,'Taux de change'!$A$5:$A$8,0))) | I11: Espèces
A12: 16h00–17h00 | B12: Cathédrale de Puno + Plaza de Armas + Casa del Corregidor | D12: PEN | E12: 0 | F12: 10 | G12: =IF($D12="","",E12/INDEX('Taux de change'!$B$5:$B$8,MATCH($D12,'Taux de change'!$A$5:$A$8,0))) | H12: =IF($D12="","",F12/INDEX('Taux de change'!$B$5:$B$8,MATCH($D12,'Taux de change'!$A$5:$A$8,0))) | I12: Espèces
A13: 17h00–18h00 | B13: Mirador Kuntur Wasi (le condor) — mototaxi aller/retour + 100 marches | D13: PEN | E13: 10 | F13: 14 | G13: =IF($D13="","",E13/INDEX('Taux de change'!$B$5:$B$8,MATCH($D13,'Taux de change'!$A$5:$A$8,0))) | H13: =IF($D13="","",F13/INDEX('Taux de change'!$B$5:$B$8,MATCH($D13,'Taux de change'!$A$5:$A$8,0))) | I13: Espèces
A14: 18h00–18h30 | B14: Achat du billet de bus Puno → Copacabana (agence Jr. Tacna ou terminal) | C14: Trans Titicaca, Tour Perú, Trans Zela, Trans Salvador. Départ 07h30. Billet payé ici, trajet le lendemain. | D14: PEN | E14: 30 | F14: 45 | G14: =IF($D14="","",E14/INDEX('Taux de change'!$B$5:$B$8,MATCH($D14,'Taux de change'!$A$5:$A$8,0))) | H14: =IF($D14="","",F14/INDEX('Taux de change'!$B$5:$B$8,MATCH($D14,'Taux de change'!$A$5:$A$8,0))) | I14: Espèces
A15: 18h30–19h00 | B15: Change S/ → Bs en casa de cambio (Jr. Lima) et retrait DAB | C15: Frais de retrait S/ 18–25 chez BCP/Interbank. Banco de la Nación est le moins cher. Sortir de quoi tenir en Bolivie. | D15: PEN | E15: 18 | F15: 25 | G15: =IF($D15="","",E15/INDEX('Taux de change'!$B$5:$B$8,MATCH($D15,'Taux de change'!$A$5:$A$8,0))) | H15: =IF($D15="","",F15/INDEX('Taux de change'!$B$5:$B$8,MATCH($D15,'Taux de change'!$A$5:$A$8,0))) | I15: Espèces
A16: 19h30–20h30 | B16: Dîner : pizzeria au feu de bois ou anticuchos de la Plaza | D16: PEN | E16: 25 | F16: 35 | G16: =IF($D16="","",E16/INDEX('Taux de change'!$B$5:$B$8,MATCH($D16,'Taux de change'!$A$5:$A$8,0))) | H16: =IF($D16="","",F16/INDEX('Taux de change'!$B$5:$B$8,MATCH($D16,'Taux de change'!$A$5:$A$8,0))) | I16: CB / esp.
A17: — | B17: Puce Claro ou Bitel, 10 Go / 30 jours (passeport obligatoire) | D17: PEN | E17: 30 | F17: 30 | G17: =IF($D17="","",E17/INDEX('Taux de change'!$B$5:$B$8,MATCH($D17,'Taux de change'!$A$5:$A$8,0))) | H17: =IF($D17="","",F17/INDEX('Taux de change'!$B$5:$B$8,MATCH($D17,'Taux de change'!$A$5:$A$8,0))) | I17: Espèces
A19: TOTAL JOUR 2 | G19: =SUM(G6:G17) | H19: =SUM(H6:H17)
A21: Détail par devise
A22: Total S/ (PEN) | E22: =SUMIF($D$6:$D$17,"PEN",E6:E17) | F22: =SUMIF($D$6:$D$17,"PEN",F6:F17)
A24: Colonnes E et F = fourchette basse / haute en monnaie locale. Colonnes G et H = conversion automatique via la feuille « Taux de change ».

Sheet J03 - Puno-Copacabana
A1: JOUR 3 — PUNO → COPACABANA (Bolivie)
A2: Passage de frontière à Kasani — côté bolivien du Titicaca
A3: Altitude : 3 841 m
A5: Horaires | B5: Activité / prestation | C5: Détail, vigilance, alternative | D5: Devise | E5: Coût local min | F5: Coût local max | G5: Coût USD min | H5: Coût USD max | I5: Paiement
A6: 06h30–07h00 | B6: Petit-déjeuner à l'hostal (souvent inclus) | D6: PEN | E6: 0 | F6: 10 | G6: =IF($D6="","",E6/INDEX('Taux de change'!$B$5:$B$8,MATCH($D6,'Taux de change'!$A$5:$A$8,0))) | H6: =IF($D6="","",F6/INDEX('Taux de change'!$B$5:$B$8,MATCH($D6,'Taux de change'!$A$5:$A$8,0))) | I6: Espèces
A7: 07h00–07h15 | B7: Mototaxi → Terminal Terrestre | D7: PEN | E7: 5 | F7: 8 | G7: =IF($D7="","",E7/INDEX('Taux de change'!$B$5:$B$8,MATCH($D7,'Taux de change'!$A$5:$A$8,0))) | H7: =IF($D7="","",F7/INDEX('Taux de change'!$B$5:$B$8,MATCH($D7,'Taux de change'!$A$5:$A$8,0))) | I7: Espèces
A8: 07h15–07h30 | B8: Tasa de embarque du terminal de Puno | D8: PEN | E8: 1.5 | F8: 2 | G8: =IF($D8="","",E8/INDEX('Taux de change'!$B$5:$B$8,MATCH($D8,'Taux de change'!$A$5:$A$8,0))) | H8: =IF($D8="","",F8/INDEX('Taux de change'!$B$5:$B$8,MATCH($D8,'Taux de change'!$A$5:$A$8,0))) | I8: Espèces
A9: 07h30–09h30 | B9: BUS PUNO → KASANI — 150 km par la rive ouest (Chucuito, Juli, Yunguyo) | C9: Billet acheté la veille (S/ 30–45). | I9: —
A10: 09h30–10h15 | B10: FRONTIÈRE — Sortie du Pérou (Migraciones Yunguyo) : tampon de sortie | C10: Aucune taxe de sortie au Pérou. Garder la carte TAM si on vous en a donné une. | I10: GRATUIT
A11: 10h15–11h00 | B11: FRONTIÈRE — Entrée en Bolivie (Migración Kasani) : tampon 90 jours pour un passeport français | C11: Aucun visa ni frais pour les Français. Si un agent réclame une « boleta » de Bs 10–20, demandez un reçu officiel : la taxe n'existe pas. Demandez explicitement 90 jours. | I11: GRATUIT
A12: 11h00–11h15 | B12: Change $ / S/ → Bs auprès des cambistas de Kasani | C12: Taux 4–6 % moins bon qu'à La Paz : ne changez ici que Bs 300–500 de dépannage. | I12: Espèces
A13: 12h30 | B13: Arrivée Copacabana (attention : +1 h, la Bolivie est à UTC−4) | I13: —
A14: 12h30–13h00 | B14: Marche terminal → hostal (600 m, tout est à pied) | I14: —
A15: 13h00–13h30 | B15: Check-in hostal Copacabana — dortoir ou chambre privée avec vue sur le lac | C15: À Copacabana, la quasi-totalité des hostales n'acceptent QUE les espèces en bolivianos. | D15: BOB | E15: 60 | F15: 110 | G15: =IF($D15="","",E15/INDEX('Taux de change'!$B$5:$B$8,MATCH($D15,'Taux de change'!$A$5:$A$8,0))) | H15: =IF($D15="","",F15/INDEX('Taux de change'!$B$5:$B$8,MATCH($D15,'Taux de change'!$A$5:$A$8,0))) | I15: Espèces
A16: 13h30–14h30 | B16: Almuerzo : trucha a la plancha, Av. 6 de Agosto | D16: BOB | E16: 30 | F16: 45 | G16: =IF($D16="","",E16/INDEX('Taux de change'!$B$5:$B$8,MATCH($D16,'Taux de change'!$A$5:$A$8,0))) | H16: =IF($D16="","",F16/INDEX('Taux de change'!$B$5:$B$8,MATCH($D16,'Taux de change'!$A$5:$A$8,0))) | I16: Espèces
A17: 14h30–16h00 | B17: Basilique Notre-Dame de Copacabana + Capilla de Velas + bénédiction des voitures (ven./dim.) | D17: BOB | E17: 0 | F17: 10 | G17: =IF($D17="","",E17/INDEX('Taux de change'!$B$5:$B$8,MATCH($D17,'Taux de change'!$A$5:$A$8,0))) | H17: =IF($D17="","",F17/INDEX('Taux de change'!$B$5:$B$8,MATCH($D17,'Taux de change'!$A$5:$A$8,0))) | I17: Espèces
A18: 16h00–18h00 | B18: Montée au Cerro Calvario (3 966 m, 45 min) — coucher de soleil sur le Titicaca | D18: BOB | E18: 0 | F18: 5 | G18: =IF($D18="","",E18/INDEX('Taux de change'!$B$5:$B$8,MATCH($D18,'Taux de change'!$A$5:$A$8,0))) | H18: =IF($D18="","",F18/INDEX('Taux de change'!$B$5:$B$8,MATCH($D18,'Taux de change'!$A$5:$A$8,0))) | I18: Espèces
A19: 18h00–18h30 | B19: Réservation du bateau pour l'Isla del Sol au muelle (départ 08h30) | C19: Paiement le lendemain matin au guichet du quai. | I19: —
A20: 19h00–20h00 | B20: Dîner : sopa de quinua + pique macho | D20: BOB | E20: 30 | F20: 45 | G20: =IF($D20="","",E20/INDEX('Taux de change'!$B$5:$B$8,MATCH($D20,'Taux de change'!$A$5:$A$8,0))) | H20: =IF($D20="","",F20/INDEX('Taux de change'!$B$5:$B$8,MATCH($D20,'Taux de change'!$A$5:$A$8,0))) | I20: Espèces
A21: — | B21: Eau 4 L + snacks (l'eau du robinet n'est pas potable) | D21: BOB | E21: 15 | F21: 15 | G21: =IF($D21="","",E21/INDEX('Taux de change'!$B$5:$B$8,MATCH($D21,'Taux de change'!$A$5:$A$8,0))) | H21: =IF($D21="","",F21/INDEX('Taux de change'!$B$5:$B$8,MATCH($D21,'Taux de change'!$A$5:$A$8,0))) | I21: Espèces
A23: TOTAL JOUR 3 | G23: =SUM(G6:G21) | H23: =SUM(H6:H21)
A25: Détail par devise
A26: Total S/ (PEN) | E26: =SUMIF($D$6:$D$21,"PEN",E6:E21) | F26: =SUMIF($D$6:$D$21,"PEN",F6:F21)
A27: Total Bs (BOB) | E27: =SUMIF($D$6:$D$21,"BOB",E6:E21) | F27: =SUMIF($D$6:$D$21,"BOB",F6:F21)
A29: Colonnes E et F = fourchette basse / haute en monnaie locale. Colonnes G et H = conversion automatique via la feuille « Taux de change ».

Sheet J04 - Isla del Sol
A1: JOUR 4 — ISLA DEL SOL (Bolivie)
A2: Journée complète sur l'île du Soleil — berceau inca
A3: Altitude : 4 070 m
A5: Horaires | B5: Activité / prestation | C5: Détail, vigilance, alternative | D5: Devise | E5: Coût local min | F5: Coût local max | G5: Coût USD min | H5: Coût USD max | I5: Paiement
A6: 07h30–08h15 | B6: Petit-déjeuner : café + salteña | D6: BOB | E6: 12 | F6: 20 | G6: =IF($D6="","",E6/INDEX('Taux de change'!$B$5:$B$8,MATCH($D6,'Taux de change'!$A$5:$A$8,0))) | H6: =IF($D6="","",F6/INDEX('Taux de change'!$B$5:$B$8,MATCH($D6,'Taux de change'!$A$5:$A$8,0))) | I6: Espèces
A7: 08h15–08h30 | B7: Billet de bateau aller-retour au muelle (Titicaca Tours / Andes Amazonía) | C7: Bs 40 si le bateau est plein (12 pers. min.), Bs 60 sinon. Aller simple Bs 25–30. | D7: BOB | E7: 40 | F7: 60 | G7: =IF($D7="","",E7/INDEX('Taux de change'!$B$5:$B$8,MATCH($D7,'Taux de change'!$A$5:$A$8,0))) | H7: =IF($D7="","",F7/INDEX('Taux de change'!$B$5:$B$8,MATCH($D7,'Taux de change'!$A$5:$A$8,0))) | I7: Espèces
A8: 08h30–10h00 | B8: BATEAU Copacabana → Yumani (sud de l'île) — 1 h 30 de navigation | I8: —
A9: 10h00–10h15 | B9: Ticket communautaire — secteur sud (communauté de Yumani) | D9: BOB | E9: 25 | F9: 25 | G9: =IF($D9="","",E9/INDEX('Taux de change'!$B$5:$B$8,MATCH($D9,'Taux de change'!$A$5:$A$8,0))) | H9: =IF($D9="","",F9/INDEX('Taux de change'!$B$5:$B$8,MATCH($D9,'Taux de change'!$A$5:$A$8,0))) | I9: Espèces (exact)
A10: 10h15–11h15 | B10: Escalier de l'Inca (206 marches) + Fuente del Inca (3 sources) | C10: Montée très rude à 4 000 m avec le sac : laissez vos affaires à Copacabana. | I10: —
A11: 11h15–13h00 | B11: Sentier de crête sud → Pilko Kaina (temple du Soleil) + Museo de Oro | D11: BOB | E11: 15 | F11: 15 | G11: =IF($D11="","",E11/INDEX('Taux de change'!$B$5:$B$8,MATCH($D11,'Taux de change'!$A$5:$A$8,0))) | H11: =IF($D11="","",F11/INDEX('Taux de change'!$B$5:$B$8,MATCH($D11,'Taux de change'!$A$5:$A$8,0))) | I11: Espèces (exact)
A12: 13h00–14h00 | B12: Déjeuner sur l'île (trucha + vue) — prix majorés, tout est monté à dos d'âne | D12: BOB | E12: 40 | F12: 55 | G12: =IF($D12="","",E12/INDEX('Taux de change'!$B$5:$B$8,MATCH($D12,'Taux de change'!$A$5:$A$8,0))) | H12: =IF($D12="","",F12/INDEX('Taux de change'!$B$5:$B$8,MATCH($D12,'Taux de change'!$A$5:$A$8,0))) | I12: Espèces
A13: 14h00–15h00 | B13: Ticket communautaire — secteur nord (Challapampa, Roca Sagrada, Chincana) | C13: IMPORTANT : l'accès au nord de l'île est périodiquement fermé pour conflit entre communautés. Vérifiez AVANT d'acheter le bateau ; si c'est fermé, ce coût tombe. | D13: BOB | E13: 0 | F13: 25 | G13: =IF($D13="","",E13/INDEX('Taux de change'!$B$5:$B$8,MATCH($D13,'Taux de change'!$A$5:$A$8,0))) | H13: =IF($D13="","",F13/INDEX('Taux de change'!$B$5:$B$8,MATCH($D13,'Taux de change'!$A$5:$A$8,0))) | I13: Espèces (exact)
A14: 15h30–17h00 | B14: BATEAU retour Yumani → Copacabana | C14: Dernier départ 16h00 — ne pas le rater, il n'y a pas de suivant. | I14: —
A15: 17h00–18h30 | B15: Marché artisanal (alpaga, aguayos) + change complémentaire | D15: BOB | E15: 0 | F15: 80 | G15: =IF($D15="","",E15/INDEX('Taux de change'!$B$5:$B$8,MATCH($D15,'Taux de change'!$A$5:$A$8,0))) | H15: =IF($D15="","",F15/INDEX('Taux de change'!$B$5:$B$8,MATCH($D15,'Taux de change'!$A$5:$A$8,0))) | I15: Espèces
A16: 19h00–20h00 | B16: Dîner | D16: BOB | E16: 30 | F16: 45 | G16: =IF($D16="","",E16/INDEX('Taux de change'!$B$5:$B$8,MATCH($D16,'Taux de change'!$A$5:$A$8,0))) | H16: =IF($D16="","",F16/INDEX('Taux de change'!$B$5:$B$8,MATCH($D16,'Taux de change'!$A$5:$A$8,0))) | I16: Espèces
A17: Nuit | B17: Hostal Copacabana (2ᵉ nuit) | D17: BOB | E17: 60 | F17: 110 | G17: =IF($D17="","",E17/INDEX('Taux de change'!$B$5:$B$8,MATCH($D17,'Taux de change'!$A$5:$A$8,0))) | H17: =IF($D17="","",F17/INDEX('Taux de change'!$B$5:$B$8,MATCH($D17,'Taux de change'!$A$5:$A$8,0))) | I17: Espèces
A19: TOTAL JOUR 4 | G19: =SUM(G6:G17) | H19: =SUM(H6:H17)
A21: Détail par devise
A22: Total Bs (BOB) | E22: =SUMIF($D$6:$D$17,"BOB",E6:E17) | F22: =SUMIF($D$6:$D$17,"BOB",F6:F17)
A24: Colonnes E et F = fourchette basse / haute en monnaie locale. Colonnes G et H = conversion automatique via la feuille « Taux de change ».

Sheet J05 - Copacabana-La Paz
A1: JOUR 5 — COPACABANA → LA PAZ
A2: Détroit de Tiquina et descente sur La Paz
A3: Altitude : 3 640 m
A5: Horaires | B5: Activité / prestation | C5: Détail, vigilance, alternative | D5: Devise | E5: Coût local min | F5: Coût local max | G5: Coût USD min | H5: Coût USD max | I5: Paiement
A6: 07h30–08h15 | B6: Petit-déjeuner | D6: BOB | E6: 12 | F6: 20 | G6: =IF($D6="","",E6/INDEX('Taux de change'!$B$5:$B$8,MATCH($D6,'Taux de change'!$A$5:$A$8,0))) | H6: =IF($D6="","",F6/INDEX('Taux de change'!$B$5:$B$8,MATCH($D6,'Taux de change'!$A$5:$A$8,0))) | I6: Espèces
A7: 08h15–11h00 | B7: Matinée libre : Horca del Inca (observatoire pré-inca, 30 min de montée) et plage | D7: BOB | E7: 10 | F7: 15 | G7: =IF($D7="","",E7/INDEX('Taux de change'!$B$5:$B$8,MATCH($D7,'Taux de change'!$A$5:$A$8,0))) | H7: =IF($D7="","",F7/INDEX('Taux de change'!$B$5:$B$8,MATCH($D7,'Taux de change'!$A$5:$A$8,0))) | I7: Espèces
A8: 11h00–12h30 | B8: Almuerzo + courses pour la route | D8: BOB | E8: 30 | F8: 45 | G8: =IF($D8="","",E8/INDEX('Taux de change'!$B$5:$B$8,MATCH($D8,'Taux de change'!$A$5:$A$8,0))) | H8: =IF($D8="","",F8/INDEX('Taux de change'!$B$5:$B$8,MATCH($D8,'Taux de change'!$A$5:$A$8,0))) | I8: Espèces
A9: 12h30–13h15 | B9: Achat du billet — bus public (Manco Kapac, Trans Titicaca : Bs 30–40) ou bus touristique porte-à-porte (Bolivia Hop, Titicaca Bolivia : Bs 80–100) | C9: Le bus public part du parc central, le touristique vous dépose à l'hôtel à La Paz. | D9: BOB | E9: 30 | F9: 100 | G9: =IF($D9="","",E9/INDEX('Taux de change'!$B$5:$B$8,MATCH($D9,'Taux de change'!$A$5:$A$8,0))) | H9: =IF($D9="","",F9/INDEX('Taux de change'!$B$5:$B$8,MATCH($D9,'Taux de change'!$A$5:$A$8,0))) | I9: Espèces
A10: 13h30–14h45 | B10: BUS Copacabana → San Pablo de Tiquina (45 km) | I10: —
A11: 14h45–15h15 | B11: DÉTROIT DE TIQUINA — vous traversez en barque à moteur, le bus passe sur une barge en bois | C11: JAMAIS inclus dans le billet. Prévoyez la monnaie exacte, on ne rend pas. | D11: BOB | E11: 2 | F11: 3 | G11: =IF($D11="","",E11/INDEX('Taux de change'!$B$5:$B$8,MATCH($D11,'Taux de change'!$A$5:$A$8,0))) | H11: =IF($D11="","",F11/INDEX('Taux de change'!$B$5:$B$8,MATCH($D11,'Taux de change'!$A$5:$A$8,0))) | I11: Espèces (exact)
A12: 15h15–17h30 | B12: Route Tiquina → La Paz (155 km) par l'Altiplano, entrée par El Alto et la descente sur la cuvette | I12: —
A13: 17h30–18h00 | B13: Arrivée (Cementerio pour les bus publics / Terminal pour les autres) + taxi vers Sopocachi ou San Pedro | C13: Quartier Cementerio peu sûr à la nuit tombée : prenez un taxi radio, pas un taxi blanc non identifié. | D13: BOB | E13: 20 | F13: 35 | G13: =IF($D13="","",E13/INDEX('Taux de change'!$B$5:$B$8,MATCH($D13,'Taux de change'!$A$5:$A$8,0))) | H13: =IF($D13="","",F13/INDEX('Taux de change'!$B$5:$B$8,MATCH($D13,'Taux de change'!$A$5:$A$8,0))) | I13: Espèces
A14: 18h00–18h30 | B14: Check-in hostel La Paz — lit en dortoir (privée : Bs 180–280) | D14: BOB | E14: 70 | F14: 125 | G14: =IF($D14="","",E14/INDEX('Taux de change'!$B$5:$B$8,MATCH($D14,'Taux de change'!$A$5:$A$8,0))) | H14: =IF($D14="","",F14/INDEX('Taux de change'!$B$5:$B$8,MATCH($D14,'Taux de change'!$A$5:$A$8,0))) | I14: CB / esp.
A15: 19h00–20h30 | B15: Dîner à Sopocachi : plat + bière Paceña | C15: Majoration de 5 % fréquente en cas de paiement par carte. | D15: BOB | E15: 45 | F15: 70 | G15: =IF($D15="","",E15/INDEX('Taux de change'!$B$5:$B$8,MATCH($D15,'Taux de change'!$A$5:$A$8,0))) | H15: =IF($D15="","",F15/INDEX('Taux de change'!$B$5:$B$8,MATCH($D15,'Taux de change'!$A$5:$A$8,0))) | I15: CB / esp.
A16: — | B16: Retrait au DAB (BCP, Banco Unión, Mercantil Santa Cruz) | C16: Plafonds fréquents de Bs 700–2 000 par retrait et DAB souvent vides le week-end. Retirez tôt et large. | D16: BOB | E16: 25 | F16: 35 | G16: =IF($D16="","",E16/INDEX('Taux de change'!$B$5:$B$8,MATCH($D16,'Taux de change'!$A$5:$A$8,0))) | H16: =IF($D16="","",F16/INDEX('Taux de change'!$B$5:$B$8,MATCH($D16,'Taux de change'!$A$5:$A$8,0))) | I16: Espèces
A18: TOTAL JOUR 5 | G18: =SUM(G6:G16) | H18: =SUM(H6:H16)
A20: Détail par devise
A21: Total Bs (BOB) | E21: =SUMIF($D$6:$D$16,"BOB",E6:E16) | F21: =SUMIF($D$6:$D$16,"BOB",F6:F16)
A23: Colonnes E et F = fourchette basse / haute en monnaie locale. Colonnes G et H = conversion automatique via la feuille « Taux de change ».

Sheet J06 - La Paz 1
A1: JOUR 6 — LA PAZ — jour 1
A2: Téléphériques, El Alto, marchés et miradors
A3: Altitude : 3 640 m
A5: Horaires | B5: Activité / prestation | C5: Détail, vigilance, alternative | D5: Devise | E5: Coût local min | F5: Coût local max | G5: Coût USD min | H5: Coût USD max | I5: Paiement
A6: 07h30–08h30 | B6: Petit-déjeuner : api con pastel au Mercado Rodríguez | D6: BOB | E6: 10 | F6: 18 | G6: =IF($D6="","",E6/INDEX('Taux de change'!$B$5:$B$8,MATCH($D6,'Taux de change'!$A$5:$A$8,0))) | H6: =IF($D6="","",F6/INDEX('Taux de change'!$B$5:$B$8,MATCH($D6,'Taux de change'!$A$5:$A$8,0))) | I6: Espèces
A7: 09h00–12h00 | B7: Free walking tour (Red Cap Walking Tours, départ 11h00 Plaza San Pedro) — pourboire attendu | D7: BOB | E7: 50 | F7: 80 | G7: =IF($D7="","",E7/INDEX('Taux de change'!$B$5:$B$8,MATCH($D7,'Taux de change'!$A$5:$A$8,0))) | H7: =IF($D7="","",F7/INDEX('Taux de change'!$B$5:$B$8,MATCH($D7,'Taux de change'!$A$5:$A$8,0))) | I7: Espèces
A8: 12h00–12h15 | B8: Mi Teleférico — ligne Rouge : Estación Central → El Alto (16 de Julio), 4 000 m | D8: BOB | E8: 3 | F8: 3 | G8: =IF($D8="","",E8/INDEX('Taux de change'!$B$5:$B$8,MATCH($D8,'Taux de change'!$A$5:$A$8,0))) | H8: =IF($D8="","",F8/INDEX('Taux de change'!$B$5:$B$8,MATCH($D8,'Taux de change'!$A$5:$A$8,0))) | I8: Espèces / QR
A9: 12h15–13h30 | B9: Mirador d'El Alto sur toute la cuvette + Feria 16 de Julio (jeudi et dimanche, l'un des plus grands marchés d'Amérique du Sud) | C9: Pickpockets nombreux à la Feria : sac devant, pas de téléphone en main. | I9: —
A10: 13h30–14h30 | B10: Almuerzo complet (sopa + segundo + refresco) dans un comedor local | D10: BOB | E10: 20 | F10: 35 | G10: =IF($D10="","",E10/INDEX('Taux de change'!$B$5:$B$8,MATCH($D10,'Taux de change'!$A$5:$A$8,0))) | H10: =IF($D10="","",F10/INDEX('Taux de change'!$B$5:$B$8,MATCH($D10,'Taux de change'!$A$5:$A$8,0))) | I10: Espèces
A11: 14h30–14h45 | B11: Mi Teléferico — lignes Bleue puis Blanche (retour + vue sur l'Illimani) | D11: BOB | E11: 5 | F11: 6 | G11: =IF($D11="","",E11/INDEX('Taux de change'!$B$5:$B$8,MATCH($D11,'Taux de change'!$A$5:$A$8,0))) | H11: =IF($D11="","",F11/INDEX('Taux de change'!$B$5:$B$8,MATCH($D11,'Taux de change'!$A$5:$A$8,0))) | I11: Espèces / QR
A12: 15h00–16h00 | B12: Mercado de las Brujas + Calle Sagárnaga + Calle Jaén (rue coloniale) | I12: —
A13: 16h00–17h00 | B13: Musée San Francisco : cloître, catacombes, toits | D13: BOB | E13: 25 | F13: 30 | G13: =IF($D13="","",E13/INDEX('Taux de change'!$B$5:$B$8,MATCH($D13,'Taux de change'!$A$5:$A$8,0))) | H13: =IF($D13="","",F13/INDEX('Taux de change'!$B$5:$B$8,MATCH($D13,'Taux de change'!$A$5:$A$8,0))) | I13: Espèces
A14: 17h00–18h00 | B14: Museo Nacional de Etnografía y Folklore (MUSEF) | D14: BOB | E14: 20 | F14: 20 | G14: =IF($D14="","",E14/INDEX('Taux de change'!$B$5:$B$8,MATCH($D14,'Taux de change'!$A$5:$A$8,0))) | H14: =IF($D14="","",F14/INDEX('Taux de change'!$B$5:$B$8,MATCH($D14,'Taux de change'!$A$5:$A$8,0))) | I14: Espèces
A15: 18h00–18h30 | B15: Taxi → Mirador Killi Killi, coucher de soleil sur la cuvette | D15: BOB | E15: 25 | F15: 35 | G15: =IF($D15="","",E15/INDEX('Taux de change'!$B$5:$B$8,MATCH($D15,'Taux de change'!$A$5:$A$8,0))) | H15: =IF($D15="","",F15/INDEX('Taux de change'!$B$5:$B$8,MATCH($D15,'Taux de change'!$A$5:$A$8,0))) | I15: Espèces
A16: 19h30–21h00 | B16: Dîner (Popular Cocina Boliviana, Ali Pacha ou marché Sopocachi) | D16: BOB | E16: 45 | F16: 80 | G16: =IF($D16="","",E16/INDEX('Taux de change'!$B$5:$B$8,MATCH($D16,'Taux de change'!$A$5:$A$8,0))) | H16: =IF($D16="","",F16/INDEX('Taux de change'!$B$5:$B$8,MATCH($D16,'Taux de change'!$A$5:$A$8,0))) | I16: CB / esp.
A17: — | B17: ACHAT DU BILLET La Paz → Santa Cruz (Trans Copacabana, El Dorado) — bus cama, départ 19h–20h | C17: Tarif officiel homologué par l'ATT depuis le 02/01/2026 : Bs 232–308 par la route neuve, Bs 246–319 par l'ancienne. Refusez tout prix supérieur. | D17: BOB | E17: 232 | F17: 319 | G17: =IF($D17="","",E17/INDEX('Taux de change'!$B$5:$B$8,MATCH($D17,'Taux de change'!$A$5:$A$8,0))) | H17: =IF($D17="","",F17/INDEX('Taux de change'!$B$5:$B$8,MATCH($D17,'Taux de change'!$A$5:$A$8,0))) | I17: CB / esp.
A18: Nuit | B18: Hostel La Paz (2ᵉ nuit) | D18: BOB | E18: 70 | F18: 125 | G18: =IF($D18="","",E18/INDEX('Taux de change'!$B$5:$B$8,MATCH($D18,'Taux de change'!$A$5:$A$8,0))) | H18: =IF($D18="","",F18/INDEX('Taux de change'!$B$5:$B$8,MATCH($D18,'Taux de change'!$A$5:$A$8,0))) | I18: CB / esp.
A20: TOTAL JOUR 6 | G20: =SUM(G6:G18) | H20: =SUM(H6:H18)
A22: Détail par devise
A23: Total Bs (BOB) | E23: =SUMIF($D$6:$D$18,"BOB",E6:E18) | F23: =SUMIF($D$6:$D$18,"BOB",F6:F18)
A25: Colonnes E et F = fourchette basse / haute en monnaie locale. Colonnes G et H = conversion automatique via la feuille « Taux de change ».

Sheet J07 - La Paz 2
A1: JOUR 7 — LA PAZ — jour 2
A2: Route de la Mort à VTT, puis bus de nuit vers Santa Cruz
A3: Altitude : 4 650 → 1 200 m
A5: Horaires | B5: Activité / prestation | C5: Détail, vigilance, alternative | D5: Devise | E5: Coût local min | F5: Coût local max | G5: Coût USD min | H5: Coût USD max | I5: Paiement
A6: 06h45–07h15 | B6: Petit-déjeuner (inclus dans le tour) | I6: —
A7: 07h15–08h00 | B7: Ramassage à l'agence → La Cumbre (4 650 m) | I7: —
A8: 08h00–15h30 | B8: ROUTE DE LA MORT À VTT — 64 km, 3 500 m de descente, de 4 650 m à 1 200 m (Coroico/Yolosa). Inclus : VTT à double suspension, casque intégral, protections, guide, van suiveur, snacks, déjeuner, douche et T-shirt | C8: Ne prenez QUE Gravity, Vertigo, Barracuda ou Altitude : il y a des morts chaque année chez les agences à Bs 400. Payable en $ ou Bs ; carte souvent +5 %. | D8: BOB | E8: 900 | F8: 1320 | G8: =IF($D8="","",E8/INDEX('Taux de change'!$B$5:$B$8,MATCH($D8,'Taux de change'!$A$5:$A$8,0))) | H8: =IF($D8="","",F8/INDEX('Taux de change'!$B$5:$B$8,MATCH($D8,'Taux de change'!$A$5:$A$8,0))) | I8: CB / esp.
A9: — | B9: ALTERNATIVE ÉCONOMIQUE au lieu du VTT : Valle de la Luna (Bs 30) + Muela del Diablo + Valle de las Ánimas en tour partagé — Bs 150–220 ($12,5–18) | C9: Non additionné ci-dessous : si vous choisissez cette option, retirez environ Bs 900–1 320 ($75–110) du total du jour. | I9: Espèces
A10: 15h30–18h30 | B10: Retour vers La Paz (remontée par la nouvelle route des Yungas) | I10: —
A11: 18h30–19h00 | B11: Récupération des sacs à l'hostel + taxi → Terminal de Buses (Plaza Antofagasta) | D11: BOB | E11: 20 | F11: 30 | G11: =IF($D11="","",E11/INDEX('Taux de change'!$B$5:$B$8,MATCH($D11,'Taux de change'!$A$5:$A$8,0))) | H11: =IF($D11="","",F11/INDEX('Taux de change'!$B$5:$B$8,MATCH($D11,'Taux de change'!$A$5:$A$8,0))) | I11: Espèces
A12: 19h00–19h15 | B12: Tasa de uso du terminal de La Paz | D12: BOB | E12: 2.5 | F12: 3.5 | G12: =IF($D12="","",E12/INDEX('Taux de change'!$B$5:$B$8,MATCH($D12,'Taux de change'!$A$5:$A$8,0))) | H12: =IF($D12="","",F12/INDEX('Taux de change'!$B$5:$B$8,MATCH($D12,'Taux de change'!$A$5:$A$8,0))) | I12: Espèces (exact)
A13: 19h15–19h45 | B13: Courses pour 18 h de route : 3 L d'eau, pain, fruits secs, papier toilette | D13: BOB | E13: 25 | F13: 40 | G13: =IF($D13="","",E13/INDEX('Taux de change'!$B$5:$B$8,MATCH($D13,'Taux de change'!$A$5:$A$8,0))) | H13: =IF($D13="","",F13/INDEX('Taux de change'!$B$5:$B$8,MATCH($D13,'Taux de change'!$A$5:$A$8,0))) | I13: Espèces
A14: 20h00 | B14: BUS LA PAZ → SANTA CRUZ — 851 km, ~18 h, bus cama. Descente de 3 640 m à 416 m | C14: Billet payé la veille. Couverture indispensable : les 6 premières heures sont glaciales, les 6 dernières tropicales. | I14: —
A15: Nuit | B15: Nuit à bord | I15: —
A17: TOTAL JOUR 7 | G17: =SUM(G6:G15) | H17: =SUM(H6:H15)
A19: Détail par devise
A20: Total Bs (BOB) | E20: =SUMIF($D$6:$D$15,"BOB",E6:E15) | F20: =SUMIF($D$6:$D$15,"BOB",F6:F15)
A22: Colonnes E et F = fourchette basse / haute en monnaie locale. Colonnes G et H = conversion automatique via la feuille « Taux de change ».

Sheet J08 - Santa Cruz
A1: JOUR 8 — SANTA CRUZ (transit)
A2: Escale de 6 h puis départ pour le Chaco
A3: Altitude : 416 m
A5: Horaires | B5: Activité / prestation | C5: Détail, vigilance, alternative | D5: Devise | E5: Coût local min | F5: Coût local max | G5: Coût USD min | H5: Coût USD max | I5: Paiement
A6: 13h00–13h30 | B6: Arrivée Terminal Bimodal de Santa Cruz (chaleur 30–34 °C, humidité) | I6: —
A7: 13h30–13h45 | B7: Consigne à bagages (guarda equipaje), 6 h | D7: BOB | E7: 15 | F7: 25 | G7: =IF($D7="","",E7/INDEX('Taux de change'!$B$5:$B$8,MATCH($D7,'Taux de change'!$A$5:$A$8,0))) | H7: =IF($D7="","",F7/INDEX('Taux de change'!$B$5:$B$8,MATCH($D7,'Taux de change'!$A$5:$A$8,0))) | I7: Espèces
A8: 13h45–14h15 | B8: ACHAT DU BILLET Santa Cruz → Asunción — Stel Turismo ou Río Paraguay, départ 19h00 (lun, mar, mer, ven, sam) | C8: Prix au guichet du terminal. Les agences internationales en ligne (Busbud, Plataforma10) affichent $85–100 pour le même siège : achetez sur place. Réservez dès votre arrivée le matin, il n'y a qu'un départ par jour. | D8: BOB | E8: 400 | F8: 520 | G8: =IF($D8="","",E8/INDEX('Taux de change'!$B$5:$B$8,MATCH($D8,'Taux de change'!$A$5:$A$8,0))) | H8: =IF($D8="","",F8/INDEX('Taux de change'!$B$5:$B$8,MATCH($D8,'Taux de change'!$A$5:$A$8,0))) | I8: Espèces
A9: 14h15–15h00 | B9: Micro n° 12 ou taxi → Plaza 24 de Septiembre | D9: BOB | E9: 2.3 | F9: 30 | G9: =IF($D9="","",E9/INDEX('Taux de change'!$B$5:$B$8,MATCH($D9,'Taux de change'!$A$5:$A$8,0))) | H9: =IF($D9="","",F9/INDEX('Taux de change'!$B$5:$B$8,MATCH($D9,'Taux de change'!$A$5:$A$8,0))) | I9: Espèces
A10: 15h00–16h00 | B10: Almuerzo cruceño : majadito ou pollo a la broaster | D10: BOB | E10: 30 | F10: 45 | G10: =IF($D10="","",E10/INDEX('Taux de change'!$B$5:$B$8,MATCH($D10,'Taux de change'!$A$5:$A$8,0))) | H10: =IF($D10="","",F10/INDEX('Taux de change'!$B$5:$B$8,MATCH($D10,'Taux de change'!$A$5:$A$8,0))) | I10: Espèces
A11: 16h00–17h30 | B11: Catedral Basílica de San Lorenzo (montée au clocher) + Casco Viejo + Manzana Uno | D11: BOB | E11: 10 | F11: 20 | G11: =IF($D11="","",E11/INDEX('Taux de change'!$B$5:$B$8,MATCH($D11,'Taux de change'!$A$5:$A$8,0))) | H11: =IF($D11="","",F11/INDEX('Taux de change'!$B$5:$B$8,MATCH($D11,'Taux de change'!$A$5:$A$8,0))) | I11: Espèces
A12: 17h30–18h00 | B12: Retour au terminal + récupération des sacs | D12: BOB | E12: 10 | F12: 30 | G12: =IF($D12="","",E12/INDEX('Taux de change'!$B$5:$B$8,MATCH($D12,'Taux de change'!$A$5:$A$8,0))) | H12: =IF($D12="","",F12/INDEX('Taux de change'!$B$5:$B$8,MATCH($D12,'Taux de change'!$A$5:$A$8,0))) | I12: Espèces
A13: 18h00–18h45 | B13: PROVISIONS OBLIGATOIRES POUR LE CHACO : 5–6 L d'eau, pain, fruits secs, papier toilette, gel hydroalcoolique, répulsif | C13: 24 h de route dans le Chaco sec : quasiment aucun service entre Villamontes et Mariscal Estigarribia. | D13: BOB | E13: 60 | F13: 90 | G13: =IF($D13="","",E13/INDEX('Taux de change'!$B$5:$B$8,MATCH($D13,'Taux de change'!$A$5:$A$8,0))) | H13: =IF($D13="","",F13/INDEX('Taux de change'!$B$5:$B$8,MATCH($D13,'Taux de change'!$A$5:$A$8,0))) | I13: Espèces
A14: 18h45–19h00 | B14: Tasa de uso du Terminal Bimodal | D14: BOB | E14: 5 | F14: 8 | G14: =IF($D14="","",E14/INDEX('Taux de change'!$B$5:$B$8,MATCH($D14,'Taux de change'!$A$5:$A$8,0))) | H14: =IF($D14="","",F14/INDEX('Taux de change'!$B$5:$B$8,MATCH($D14,'Taux de change'!$A$5:$A$8,0))) | I14: Espèces (exact)
A15: 19h00 | B15: BUS SANTA CRUZ → ASUNCIÓN — 1 324 km, ~24 h, via Abapó, Camiri, Villamontes, Ruta Transchaco | C15: Billet payé le matin. Route partiellement dégradée après Villamontes, climatisation aléatoire. | I15: —
A16: — | B16: CONTRÔLE : carnet de vaccination fièvre jaune exigé à l'entrée au Paraguay (voir Annexe B) | I16: —
A18: TOTAL JOUR 8 | G18: =SUM(G6:G16) | H18: =SUM(H6:H16)
A20: Détail par devise
A21: Total Bs (BOB) | E21: =SUMIF($D$6:$D$16,"BOB",E6:E16) | F21: =SUMIF($D$6:$D$16,"BOB",F6:F16)
A23: Colonnes E et F = fourchette basse / haute en monnaie locale. Colonnes G et H = conversion automatique via la feuille « Taux de change ».

Sheet J09 - Chaco-Asuncion
A1: JOUR 9 — CHACO → ASUNCIÓN (Paraguay)
A2: Traversée du Chaco et double frontière
A3: Altitude : 43 m
A5: Horaires | B5: Activité / prestation | C5: Détail, vigilance, alternative | D5: Devise | E5: Coût local min | F5: Coût local max | G5: Coût USD min | H5: Coût USD max | I5: Paiement
A6: 05h00–06h00 | B6: Arrêt petit-déjeuner à Villamontes | C6: Dernière occasion de dépenser vos bolivianos : ils ne valent rien au Paraguay. | D6: BOB | E6: 15 | F6: 25 | G6: =IF($D6="","",E6/INDEX('Taux de change'!$B$5:$B$8,MATCH($D6,'Taux de change'!$A$5:$A$8,0))) | H6: =IF($D6="","",F6/INDEX('Taux de change'!$B$5:$B$8,MATCH($D6,'Taux de change'!$A$5:$A$8,0))) | I6: Espèces
A7: 07h00–08h30 | B7: FRONTIÈRE — Sortie de Bolivie (poste d'Ibibobo / Villamontes) : tampon de sortie | C7: Aucune taxe de sortie officielle. Refusez poliment toute demande de « propina ». | I7: GRATUIT
A8: 08h30–10h00 | B8: No man's land d'Infante Rivarola — 100 km de Chaco sec, aucun service | I8: —
A9: 10h00–12h00 | B9: FRONTIÈRE — Entrée au Paraguay (Migraciones + contrôle sanitaire + fouille douanière) | C9: Pas de visa ni de frais pour les Français (90 jours). CARNET INTERNATIONAL DE VACCINATION FIÈVRE JAUNE OBLIGATOIRE (Résolution 268/2025) car vous venez du département de Santa Cruz, classé zone à risque. | I9: GRATUIT
A10: 12h00–13h00 | B10: Déjeuner à Mariscal Estigarribia ou Filadelfia (colonie mennonite) : empanadas, sopa paraguaya | D10: PYG | E10: 25000 | F10: 45000 | G10: =IF($D10="","",E10/INDEX('Taux de change'!$B$5:$B$8,MATCH($D10,'Taux de change'!$A$5:$A$8,0))) | H10: =IF($D10="","",F10/INDEX('Taux de change'!$B$5:$B$8,MATCH($D10,'Taux de change'!$A$5:$A$8,0))) | I10: Espèces
A11: 13h00–19h00 | B11: Ruta Transchaco : Loma Plata, Pozo Colorado, Villa Hayes, traversée du fleuve Paraguay | I11: —
A12: 19h00–20h00 | B12: Arrivée Terminal de Ómnibus de Asunción (Av. Fernando de la Mora) | C12: Le Paraguay est à UTC−3 : +1 h par rapport à la Bolivie. | I12: —
A13: 20h00–20h30 | B13: Bolt ou Uber terminal → centre / Villa Morra (6 km) | C13: Bolt est 20–30 % moins cher qu'Uber à Asunción. Taxi de rue : Gs 70 000–90 000 pour le même trajet. | D13: PYG | E13: 30000 | F13: 45000 | G13: =IF($D13="","",E13/INDEX('Taux de change'!$B$5:$B$8,MATCH($D13,'Taux de change'!$A$5:$A$8,0))) | H13: =IF($D13="","",F13/INDEX('Taux de change'!$B$5:$B$8,MATCH($D13,'Taux de change'!$A$5:$A$8,0))) | I13: CB (in-app)
A14: 20h30–21h00 | B14: Check-in hostel Asunción — lit en dortoir (privée : Gs 200 000–280 000) | D14: PYG | E14: 90000 | F14: 150000 | G14: =IF($D14="","",E14/INDEX('Taux de change'!$B$5:$B$8,MATCH($D14,'Taux de change'!$A$5:$A$8,0))) | H14: =IF($D14="","",F14/INDEX('Taux de change'!$B$5:$B$8,MATCH($D14,'Taux de change'!$A$5:$A$8,0))) | I14: CB / esp.
A15: 21h00–22h00 | B15: Dîner : asado ou lomito árabe + tereré | D15: PYG | E15: 45000 | F15: 75000 | G15: =IF($D15="","",E15/INDEX('Taux de change'!$B$5:$B$8,MATCH($D15,'Taux de change'!$A$5:$A$8,0))) | H15: =IF($D15="","",F15/INDEX('Taux de change'!$B$5:$B$8,MATCH($D15,'Taux de change'!$A$5:$A$8,0))) | I15: CB / esp.
A17: TOTAL JOUR 9 | G17: =SUM(G6:G15) | H17: =SUM(H6:H15)
A19: Détail par devise
A20: Total Bs (BOB) | E20: =SUMIF($D$6:$D$15,"BOB",E6:E15) | F20: =SUMIF($D$6:$D$15,"BOB",F6:F15)
A21: Total Gs (PYG) | E21: =SUMIF($D$6:$D$15,"PYG",E6:E15) | F21: =SUMIF($D$6:$D$15,"PYG",F6:F15)
A23: Colonnes E et F = fourchette basse / haute en monnaie locale. Colonnes G et H = conversion automatique via la feuille « Taux de change ».

Sheet J10 - Asuncion 1
A1: JOUR 10 — ASUNCIÓN — jour 1
A2: Centre historique, Mercado 4 et Costanera
A3: Altitude : 43 m
A5: Horaires | B5: Activité / prestation | C5: Détail, vigilance, alternative | D5: Devise | E5: Coût local min | F5: Coût local max | G5: Coût USD min | H5: Coût USD max | I5: Paiement
A6: 07h30–08h30 | B6: Petit-déjeuner : cocido quemado + chipa | D6: PYG | E6: 15000 | F6: 25000 | G6: =IF($D6="","",E6/INDEX('Taux de change'!$B$5:$B$8,MATCH($D6,'Taux de change'!$A$5:$A$8,0))) | H6: =IF($D6="","",F6/INDEX('Taux de change'!$B$5:$B$8,MATCH($D6,'Taux de change'!$A$5:$A$8,0))) | I6: Espèces
A7: 08h30–09h00 | B7: Bus urbain (ligne 30) ou Bolt → centre historique | C7: Les bus urbains d'Asunción n'acceptent plus les espèces : il faut la carte rechargeable « Billetaje Electrónico » (Gs 10 000 la carte). En pratique, Bolt est plus simple pour 2 jours. | D7: PYG | E7: 3500 | F7: 25000 | G7: =IF($D7="","",E7/INDEX('Taux de change'!$B$5:$B$8,MATCH($D7,'Taux de change'!$A$5:$A$8,0))) | H7: =IF($D7="","",F7/INDEX('Taux de change'!$B$5:$B$8,MATCH($D7,'Taux de change'!$A$5:$A$8,0))) | I7: Carte Más / CB
A8: 09h00–09h45 | B8: Panteón Nacional de los Héroes (gratuit, don bienvenu) + relève de la garde | D8: PYG | E8: 0 | F8: 10000 | G8: =IF($D8="","",E8/INDEX('Taux de change'!$B$5:$B$8,MATCH($D8,'Taux de change'!$A$5:$A$8,0))) | H8: =IF($D8="","",F8/INDEX('Taux de change'!$B$5:$B$8,MATCH($D8,'Taux de change'!$A$5:$A$8,0))) | I8: Espèces
A9: 09h45–10h30 | B9: Casa de la Independencia (1772) — gratuit | I9: —
A10: 10h30–11h15 | B10: Cabildo / Centro Cultural de la República — gratuit | I10: —
A11: 11h15–12h00 | B11: Palacio de los López (extérieur) + promenade sur la Costanera | I11: —
A12: 12h00–13h00 | B12: Almuerzo au Mercado 4 : bife koygua, sopa paraguaya, mbejú | D12: PYG | E12: 30000 | F12: 50000 | G12: =IF($D12="","",E12/INDEX('Taux de change'!$B$5:$B$8,MATCH($D12,'Taux de change'!$A$5:$A$8,0))) | H12: =IF($D12="","",F12/INDEX('Taux de change'!$B$5:$B$8,MATCH($D12,'Taux de change'!$A$5:$A$8,0))) | I12: Espèces
A13: 13h00–14h30 | B13: Mercado 4 : herbes médicinales (pohã ñana), artisanat ñandutí, cuir | D13: PYG | E13: 0 | F13: 60000 | G13: =IF($D13="","",E13/INDEX('Taux de change'!$B$5:$B$8,MATCH($D13,'Taux de change'!$A$5:$A$8,0))) | H13: =IF($D13="","",F13/INDEX('Taux de change'!$B$5:$B$8,MATCH($D13,'Taux de change'!$A$5:$A$8,0))) | I13: Espèces
A14: 15h00–17h00 | B14: Museo del Barro — art indigène, populaire et contemporain (le meilleur musée du pays) | C14: Entrée gratuite le vendredi et le samedi. Ouvert mar.–sam. 14h–20h uniquement. | D14: PYG | E14: 0 | F14: 50000 | G14: =IF($D14="","",E14/INDEX('Taux de change'!$B$5:$B$8,MATCH($D14,'Taux de change'!$A$5:$A$8,0))) | H14: =IF($D14="","",F14/INDEX('Taux de change'!$B$5:$B$8,MATCH($D14,'Taux de change'!$A$5:$A$8,0))) | I14: CB / esp.
A15: 17h00–18h30 | B15: Loma San Jerónimo (quartier coloré en escaliers) — Bolt aller/retour | D15: PYG | E15: 40000 | F15: 60000 | G15: =IF($D15="","",E15/INDEX('Taux de change'!$B$5:$B$8,MATCH($D15,'Taux de change'!$A$5:$A$8,0))) | H15: =IF($D15="","",F15/INDEX('Taux de change'!$B$5:$B$8,MATCH($D15,'Taux de change'!$A$5:$A$8,0))) | I15: CB (in-app)
A16: 19h00–20h00 | B16: Coucher de soleil sur la Bahía + tereré glacé | D16: PYG | E16: 10000 | F16: 20000 | G16: =IF($D16="","",E16/INDEX('Taux de change'!$B$5:$B$8,MATCH($D16,'Taux de change'!$A$5:$A$8,0))) | H16: =IF($D16="","",F16/INDEX('Taux de change'!$B$5:$B$8,MATCH($D16,'Taux de change'!$A$5:$A$8,0))) | I16: Espèces
A17: 20h30–22h00 | B17: Dîner : Lido Bar (face au Panthéon) ou Paulista Grill (rodízio) | D17: PYG | E17: 60000 | F17: 110000 | G17: =IF($D17="","",E17/INDEX('Taux de change'!$B$5:$B$8,MATCH($D17,'Taux de change'!$A$5:$A$8,0))) | H17: =IF($D17="","",F17/INDEX('Taux de change'!$B$5:$B$8,MATCH($D17,'Taux de change'!$A$5:$A$8,0))) | I17: CB
A18: Nuit | B18: Hostel Asunción (2ᵉ nuit) | D18: PYG | E18: 90000 | F18: 150000 | G18: =IF($D18="","",E18/INDEX('Taux de change'!$B$5:$B$8,MATCH($D18,'Taux de change'!$A$5:$A$8,0))) | H18: =IF($D18="","",F18/INDEX('Taux de change'!$B$5:$B$8,MATCH($D18,'Taux de change'!$A$5:$A$8,0))) | I18: CB / esp.
A20: TOTAL JOUR 10 | G20: =SUM(G6:G18) | H20: =SUM(H6:H18)
A22: Détail par devise
A23: Total Gs (PYG) | E23: =SUMIF($D$6:$D$18,"PYG",E6:E18) | F23: =SUMIF($D$6:$D$18,"PYG",F6:F18)
A25: Colonnes E et F = fourchette basse / haute en monnaie locale. Colonnes G et H = conversion automatique via la feuille « Taux de change ».

Sheet J11 - Asuncion 2
A1: JOUR 11 — ASUNCIÓN — jour 2
A2: Lac Ypacaraí (Areguá) et préparation du grand bus
A3: Altitude : 43 m
A5: Horaires | B5: Activité / prestation | C5: Détail, vigilance, alternative | D5: Devise | E5: Coût local min | F5: Coût local max | G5: Coût USD min | H5: Coût USD max | I5: Paiement
A6: 07h30–08h15 | B6: Petit-déjeuner | D6: PYG | E6: 15000 | F6: 25000 | G6: =IF($D6="","",E6/INDEX('Taux de change'!$B$5:$B$8,MATCH($D6,'Taux de change'!$A$5:$A$8,0))) | H6: =IF($D6="","",F6/INDEX('Taux de change'!$B$5:$B$8,MATCH($D6,'Taux de change'!$A$5:$A$8,0))) | I6: Espèces
A7: 08h30–09h30 | B7: Bus interurbain Asunción → Areguá (30 km, village des céramistes au bord du lac Ypacaraí) | D7: PYG | E7: 8000 | F7: 15000 | G7: =IF($D7="","",E7/INDEX('Taux de change'!$B$5:$B$8,MATCH($D7,'Taux de change'!$A$5:$A$8,0))) | H7: =IF($D7="","",F7/INDEX('Taux de change'!$B$5:$B$8,MATCH($D7,'Taux de change'!$A$5:$A$8,0))) | I7: Espèces
A8: 09h30–12h30 | B8: Areguá : église Nuestra Señora de la Candelaria, ateliers de céramique, mirador sur le lac, maisons coloniales | D8: PYG | E8: 0 | F8: 20000 | G8: =IF($D8="","",E8/INDEX('Taux de change'!$B$5:$B$8,MATCH($D8,'Taux de change'!$A$5:$A$8,0))) | H8: =IF($D8="","",F8/INDEX('Taux de change'!$B$5:$B$8,MATCH($D8,'Taux de change'!$A$5:$A$8,0))) | I8: Espèces
A9: 12h30–13h30 | B9: Déjeuner à Areguá (poisson du lac) | D9: PYG | E9: 30000 | F9: 50000 | G9: =IF($D9="","",E9/INDEX('Taux de change'!$B$5:$B$8,MATCH($D9,'Taux de change'!$A$5:$A$8,0))) | H9: =IF($D9="","",F9/INDEX('Taux de change'!$B$5:$B$8,MATCH($D9,'Taux de change'!$A$5:$A$8,0))) | I9: Espèces
A10: 13h30–15h00 | B10: Bus retour vers Asunción | D10: PYG | E10: 8000 | F10: 15000 | G10: =IF($D10="","",E10/INDEX('Taux de change'!$B$5:$B$8,MATCH($D10,'Taux de change'!$A$5:$A$8,0))) | H10: =IF($D10="","",F10/INDEX('Taux de change'!$B$5:$B$8,MATCH($D10,'Taux de change'!$A$5:$A$8,0))) | I10: Espèces
A11: 15h30–17h00 | B11: Manzana de la Rivera + Estación Central del Ferrocarril (1861, 1ʳᵉ gare d'Amérique du Sud) | D11: PYG | E11: 5000 | F11: 15000 | G11: =IF($D11="","",E11/INDEX('Taux de change'!$B$5:$B$8,MATCH($D11,'Taux de change'!$A$5:$A$8,0))) | H11: =IF($D11="","",F11/INDEX('Taux de change'!$B$5:$B$8,MATCH($D11,'Taux de change'!$A$5:$A$8,0))) | I11: Espèces
A12: 17h00–18h00 | B12: ACHAT DU BILLET Asunción → São Paulo au guichet du Terminal (Expreso Paraguay, Nuestra Señora de la Asunción, Pluma) | C12: $76–105 selon la classe (semi-cama / cama). Expreso Paraguay part à 07h00 et arrive à 04h26 (21 h 26). Départ à 09h20 avec Expresso Nordeste (plus long). | D12: PYG | E12: 450000 | F12: 620000 | G12: =IF($D12="","",E12/INDEX('Taux de change'!$B$5:$B$8,MATCH($D12,'Taux de change'!$A$5:$A$8,0))) | H12: =IF($D12="","",F12/INDEX('Taux de change'!$B$5:$B$8,MATCH($D12,'Taux de change'!$A$5:$A$8,0))) | I12: CB / esp.
A13: 18h00–19h00 | B13: Shopping Ciudad Nueva / pharmacie — le Paraguay est le pays le moins cher du continent pour l'électronique et les médicaments | D13: PYG | E13: 0 | F13: 100000 | G13: =IF($D13="","",E13/INDEX('Taux de change'!$B$5:$B$8,MATCH($D13,'Taux de change'!$A$5:$A$8,0))) | H13: =IF($D13="","",F13/INDEX('Taux de change'!$B$5:$B$8,MATCH($D13,'Taux de change'!$A$5:$A$8,0))) | I13: CB
A14: 19h30–21h00 | B14: Dîner d'adieu (chipa guazú, asado) | D14: PYG | E14: 60000 | F14: 110000 | G14: =IF($D14="","",E14/INDEX('Taux de change'!$B$5:$B$8,MATCH($D14,'Taux de change'!$A$5:$A$8,0))) | H14: =IF($D14="","",F14/INDEX('Taux de change'!$B$5:$B$8,MATCH($D14,'Taux de change'!$A$5:$A$8,0))) | I14: CB
A15: Nuit | B15: Hostel Asunción (3ᵉ nuit) | D15: PYG | E15: 90000 | F15: 150000 | G15: =IF($D15="","",E15/INDEX('Taux de change'!$B$5:$B$8,MATCH($D15,'Taux de change'!$A$5:$A$8,0))) | H15: =IF($D15="","",F15/INDEX('Taux de change'!$B$5:$B$8,MATCH($D15,'Taux de change'!$A$5:$A$8,0))) | I15: CB / esp.
A17: TOTAL JOUR 11 | G17: =SUM(G6:G15) | H17: =SUM(H6:H15)
A19: Détail par devise
A20: Total Gs (PYG) | E20: =SUMIF($D$6:$D$15,"PYG",E6:E15) | F20: =SUMIF($D$6:$D$15,"PYG",F6:F15)
A22: Colonnes E et F = fourchette basse / haute en monnaie locale. Colonnes G et H = conversion automatique via la feuille « Taux de change ».

Sheet J12 - Asuncion-Sao Paulo
A1: JOUR 12 — ASUNCIÓN → SÃO PAULO
A2: 21 h 30 de bus et passage au Brésil par le Pont de l'Amitié
A3: Altitude : —
A5: Horaires | B5: Activité / prestation | C5: Détail, vigilance, alternative | D5: Devise | E5: Coût local min | F5: Coût local max | G5: Coût USD min | H5: Coût USD max | I5: Paiement
A6: 05h30–06h00 | B6: Café à l'hostel | D6: PYG | E6: 10000 | F6: 20000 | G6: =IF($D6="","",E6/INDEX('Taux de change'!$B$5:$B$8,MATCH($D6,'Taux de change'!$A$5:$A$8,0))) | H6: =IF($D6="","",F6/INDEX('Taux de change'!$B$5:$B$8,MATCH($D6,'Taux de change'!$A$5:$A$8,0))) | I6: Espèces
A7: 06h00–06h30 | B7: Bolt → Terminal de Ómnibus de Asunción | D7: PYG | E7: 30000 | F7: 45000 | G7: =IF($D7="","",E7/INDEX('Taux de change'!$B$5:$B$8,MATCH($D7,'Taux de change'!$A$5:$A$8,0))) | H7: =IF($D7="","",F7/INDEX('Taux de change'!$B$5:$B$8,MATCH($D7,'Taux de change'!$A$5:$A$8,0))) | I7: CB (in-app)
A8: 06h30–07h00 | B8: Tasa de terminal + enregistrement des bagages en soute | D8: PYG | E8: 5000 | F8: 15000 | G8: =IF($D8="","",E8/INDEX('Taux de change'!$B$5:$B$8,MATCH($D8,'Taux de change'!$A$5:$A$8,0))) | H8: =IF($D8="","",F8/INDEX('Taux de change'!$B$5:$B$8,MATCH($D8,'Taux de change'!$A$5:$A$8,0))) | I8: Espèces
A9: 07h00 | B9: BUS ASUNCIÓN → SÃO PAULO — Expreso Paraguay · 1 130 km · 21 h 26 · via Coronel Oviedo, Ciudad del Este, Foz do Iguaçu, Cascavel, Curitiba | C9: Billet payé la veille. | I9: —
A10: 12h30–14h30 | B10: FRONTIÈRE — Ciudad del Este / Foz do Iguaçu (Puente de la Amistad) : descente avec TOUS les bagages, tampon de sortie du Paraguay puis tampon d'entrée au Brésil | C10: Aucun frais ni visa pour les Français (90 jours). EXIGEZ LES DEUX TAMPONS : beaucoup de bus ne s'arrêtent que côté brésilien et l'absence de tampon de sortie paraguayen vous coûtera une amende plus tard. Comptez 1 h 30–2 h. | I10: GRATUIT
A11: 14h30–15h00 | B11: Change Gs → R$ ou retrait à Foz do Iguaçu | C11: Dépensez vos derniers guaranis : ils sont inéchangeables hors du Paraguay. | I11: Espèces
A12: 15h00–16h00 | B12: Déjeuner à l'arrêt (Foz do Iguaçu ou Cascavel) — restaurant por quilo | D12: BRL | E12: 30 | F12: 50 | G12: =IF($D12="","",E12/INDEX('Taux de change'!$B$5:$B$8,MATCH($D12,'Taux de change'!$A$5:$A$8,0))) | H12: =IF($D12="","",F12/INDEX('Taux de change'!$B$5:$B$8,MATCH($D12,'Taux de change'!$A$5:$A$8,0))) | I12: CB
A13: 20h00–21h00 | B13: Dîner à l'arrêt routier | D13: BRL | E13: 25 | F13: 45 | G13: =IF($D13="","",E13/INDEX('Taux de change'!$B$5:$B$8,MATCH($D13,'Taux de change'!$A$5:$A$8,0))) | H13: =IF($D13="","",F13/INDEX('Taux de change'!$B$5:$B$8,MATCH($D13,'Taux de change'!$A$5:$A$8,0))) | I13: CB
A14: Nuit | B14: Nuit à bord | I14: —
A16: TOTAL JOUR 12 | G16: =SUM(G6:G14) | H16: =SUM(H6:H14)
A18: Détail par devise
